Workbook
Name ฉ141: RRP_1_V4_Sep25!$A$1
Name ธ160: 'Bond Buy-Sell_V4_Sep25 + Oct25'!$C$8

Sheet All Table
A2: Counterparty_Master | C2: Yellow means updated per our disscussion as of 3 Oct
A4: This table serves as the single, authoritative repository for all external and internal entities with which the bank conducts treasury business.
A6: Column Name | B6: Data Type | C6: Description | D6: Example
A7: counterparty_id | B7: INT | C7: Unique system-generated identifier for the counterparty. | D7: 101
A8: LegalName | B8: VARCHAR(255) | C8: The full legal name of the entity. | D8: Bangkok Bank PCL
A9: ShortCode | B9: VARCHAR(50) | C9: A short, unique code used for quick identification in user interfaces. | D9: BBL
A10: CounterpartyType | B10: VARCHAR(50) | C10: Type of counterparty (e.g., 'Commercial Bank', 'SOE', 'Corporate', 'Central Bank'). | D10: Commercial Bank
A11: BANK_CODE | B11: VARCHAR(11) | C11: Official identifier assigned by the Bank of Thailand. | D11: 2
A12: SWIFT_BIC | B12: VARCHAR(11) | C12: The counterparty's Business Identifier Code for SWIFT messaging. | D12: BKKBTHBK
A13: PrimaryCreditRating | B13: VARCHAR(10) | C13: The primary credit rating from the designated agency. | D13: AA+
A14: PrimaryRatingAgency | B14: VARCHAR(50) | C14: The name of the primary credit rating agency (e.g., 'Fitch', 'TRIS Rating'). | D14: TRIS Rating
A15: PrimaryRatingDate | B15: DATE | C15: The date the primary rating was assigned or last updated. | D15: 45853
A16: GMRA_AgreementID | B16: INT | C16: Links to a master table of legal agreements, crucial for REPO trades. | D16: 56
A17: CreatedDate | B17: DATE | C17: Timestamp of record creation for audit purposes. | D17: 45301
A18: LastUpdatedDate | B18: DATE | C18: Timestamp of the last update for audit purposes. | D18: 45853
A20: Security_Master
A22: This table is a comprehensive catalog of every financial instrument the bank can trade or hold, aligned with standards from the Thai Bond Market Association (ThaiBMA).
A24: Column Name | B24: Data Type | C24: Description | D24: Example | E24: Remark
A25: SecurityID | B25: INT | C25: Unique system-generated identifier for the security. | D25: 5010
A26: ISIN | B26: VARCHAR(12) | C26: International Securities Identification Number. | D26: TH0623038C09
A27: ThaiBMA_Symbol | B27: VARCHAR(10) | C27: The official trading symbol used by ThaiBMA. | D27: LB28DA
A28: IssuerID | B28: INT | C28: Identify the issuer. | D28: 1 (Govt of Thailand)
A29: UniqueID | B29: VARCHAR(20) | C29: ID for BOT report | D29: 176015 (Ministry of Finance),176017(State own enterprise),001(Bank of Thailand) | E29: https://www.bot.or.th/th/our-services/data-acquisition-publication/da-and-standard/standard-code.html
A30: InstrumentType | B30: VARCHAR(20) | C30: The type of instrument (e.g., 'T-Bill', 'Gov Bond', 'Corp Bond', 'SOE Bond', 'BOT Bond'). | D30: Gov Bond
A31: IssueDate | B31: DATE | C31: The date the security was issued. | D31: 43451
A32: MaturityDate | B32: DATE | C32: The date the security matures. | D32: 47104
A33: CouponRate | B33: DECIMAL(10,6) | C33: The nominal coupon rate. Null for zero-coupon bonds. | D33: 2.75 | E33: ถ้าเป็น floating ให้ใส่ coupon rate ล่าสุด
A34: CouponFrequency | B34: VARCHAR(20) | C34: Frequency of coupon payments (e.g., 'Semi-Annual', 'Quarterly'). | D34: Semi-Annual
A35: DayCountConvention | B35: VARCHAR(20) | C35: The convention for calculating accrued interest (e.g., 'Actual/365'). 1 | D35: Actual/365
A36: Currency | B36: VARCHAR(3) | C36: ISO 4217 currency code. | D36: THB
A37: Country | B37: VARCHAR(3) | C37: Country Code | D37: TH
A38: BondStructure | B38: VARCHAR(20) | C38: Structure of principal repayment (e.g., "ZERO", 'Bullet', 'Amortizing'). | D38: Bullet
A39: IsEligibleBOT_RepoCollateral | B39: BOOLEAN | C39: Flag indicating if the security is eligible for use in BOT's repo operations. | D39: TRUE
A40: IsEligibleCRM_Collateral | B40: BOOLEAN | C40: Flag indicating if the security meets BOT's criteria for Credit Risk Mitigation. 2 | D40: TRUE
A42: Portfolio_Master
A44: This table allows for the logical segregation of the bank's treasury positions according to their strategic intent.
A46: Column Name | B46: Data Type | C46: Description | D46: Example
A47: PortfolioID | B47: INT | C47: Unique system-generated identifier for the portfolio. | D47: 201
A48: PortfolioName | B48: VARCHAR(100) | C48: Clear accounting classification upfront (e.g., 'Amortized Cost', 'Fair Value through OCI', 'Fair Value through P&L (Trading Book)') along with Asset type (Gov, SOE, BOT, T-Bill) | D48: AMC - Govt Bonds
A49: PortfolioManager | B49: VARCHAR(100) | C49: The name or ID of the responsible manager or desk. | D49: John Doe
...

Sheet Edit_control
A2: No. | B2: Log date | C2: Action / Next Step | D2: Table / Stage | E2: Priority | F2: Status | G2: Remarks / Rationale | H2: Link/Input
A3: 1 | B3: =DATE(2025,10,14) -> 45944 | C3: Create end-to-end mock-up for Bond Buy-Side flow (FVOCI & AMC, across Gov, T-Bill, BOT, SOE) to validate structure and data flow. | D3: Bond_Positions + Bond_Trades | E3: High | F3: Completed | G3: Ensures integration between trade booking → position build-up → valuation. Essential for walkthrough with stakeholders (accounting, treasury).
A4: 2 | B4: =DATE(2025,10,14) -> 45944 | C4: Create Bond_Positions table with required fields (per discussion on 3 Oct): • UnrealizedGainLoss • InterestRateType • ReferenceRate • Margin | D4: Bond_Positions | E4: High | F4: Completed | G4: - This is a core table for inventory, valuation, and reporting. Foundation for downstream EVE / accrual / accounting treatment. - This can be linked to BOT data set of investment portfolio required by YIP.
A5: 3 | B5: =DATE(2025,10,14) -> 45944 | C5: Add field "DayCountConvention" to Interbank_Deals (per discussion on 3 Oct) | D5: Interbank_Deals | E5: High | F5: Completed | G5: Needed for interest accrual and harmonization with bond instruments. Critical for consistent yield calculations and EVE linkage.
A6: =A5+1 -> 4 | B6: =DATE(2025,10,14) -> 45944 | C6: Add key rate fields to Repo_Trades (per discussion on 3 Oct): • InterestRateType • InterestRate • ReferenceRate • Margin | D6: Repo_Trades + Limit_Utilization | E6: High | F6: Completed | G6: Aligns with interbank & bond pricing logic. Enables consistent calculation engine.
A7: =A6+1 -> 5 | B7: =DATE(2025,10,14) -> 45944 | C7: Create mock-up scenario for Repo Transaction to test Limit Utilization logic: • Cover both placement and repo limit types • Include edge cases for limit direction & utilization calculation • Validate LimitType and UtilizationDirection fields in Limit_Utilization table | D7: Repo_Trades | E7: High | F7: Completed | G7: This is critical to verify how repo transactions interact with treasury placement/repo limits. Scenario should include breach cases and intra-day netting assumptions. Coordinate with Risk & Treasury for realistic cases.
A8: =A7+1 -> 6 | B8: =DATE(2025,10,14) -> 45944 | C8: Refine Field "PortfolioName" descriptions in Portfolio_Master to align with accounting classification (AMC, FVOCI) | D8: Portfolio_Master | E8: High | F8: Completed | G8: Improves clarity and reporting alignment. Useful for both system users and accounting interface.
A9: =A8+1 -> 7 | B9: =DATE(2025,10,14) -> 45944 | C9: Add limit fields to Limit_Utilization: • LimitType (Placement vs Repo) • UtilizationDirection | D9: Limit_Utilization | E9: High | F9: Completed | G9: Supports future dashboard and regulatory reporting. Not blocking core bond flow but useful for risk/limit monitoring.
A10: =A9+1 -> 8 | B10: =DATE(2025,10,14) -> 45944 | C10: Define approach for bond position valuation - TBC with Accounting team whether to apply FIFO vs Weighted Average method for cost layering.(using Weighted avg cost) - Initially, keep transaction-level (no netting) structure. | D10: Bond_Positions | E10: High | F10: Completed | G10: Impacts how realized/unrealized gains are tracked. Affects EVE and accounting treatment. Requires alignment with policy.
A11: =A10+1 -> 9 | B11: =DATE(2025,10,14) -> 45944 | C11: Link DiscountCurveID in bond position / valuation to Market Data table or curve repository (for EVE). | D11: Bond_Positions + Market Data | E11: High | F11: Not started | G11: Needed for IRRBB and scenario valuation. Can be implemented after base table structures are stable.
A12: =A11+1 -> 10 | B12: =DATE(2025,10,14) -> 45944 | C12: Create a unique results summary table as of 30 Sep 2025 to consolidate positions and trades. | D12: ALL | E12: High | F12: Completed | G12: Needed to validate cut-off balances and reconcile mock-up vs real data.
A13: =A12+1 -> 11 | B13: =DATE(2025,10,14) -> 45944 | C13: Refine Limit_Utilization table to show limit-level view per counterparty by limit type. | D13: Limit_Utilization | E13: High | F13: Completed | G13: Improves clarity of limit reporting and ensures alignment with regulatory dashboards.
A14: =A13+1 -> 12 | B14: =DATE(2025,10,14) -> 45944 | C14: Verify that all transactions after 30 Sep 2025 are correctly captured, so that the unique result table (No. 10) reflects accurate current activity. | D14: ALL | E14: High | F14: Completed | G14: Ensures completeness and accuracy of transaction capture beyond reporting cut-off for YIP's disscusion
A15: =A14+1 -> 13 | B15: =DATE(2025,10,14) -> 45944 | C15: To create the "Bond sell" mock up scenario | D15: ALL | E15: High | F15: Not started
A16: =A15+1 -> 14 | B16: =DATE(2025,10,14) -> 45944 | C16: To create the "Margin_call" master table | D16: ALL | E16: High | F16: Not started | G16: Ideally we can add field flag Collateral type = Bond, Cash (no haircut) to chek Moody's table - HQLA whether if margin call is cash , Find the BOT notificaiton and pending CSA_Margin Repo table whether it can able contain morethan 2 collatertal
A17: =A16+1 -> 15 | B17: =DATE(2025,10,18) -> 45948 | C17: P'Yut to provide Hair cut repo the market practice BOT | D17: ALL | E17: High | F17: Completed | G17: for repo case of collateral | H17: ประกาศธนาคารแห่งประเทศไทย - ที่ สกง. 1 /2556
A18: =A17+1 -> 16 | B18: =DATE(2025,10,28) -> 45958 | C18: Create Bond_Positions_Realization_Cost table to serve realized/unrealized gain/loss | D18: ALL | E18: High | F18: Not started
A19: =A18+1 -> 17 | B19: =DATE(2025,10,29) -> 45959 | C19: Added FI_CODE from BOT website in Sheet 'BANK_CODE' for references | D19: ALL | E19: High | F19: Completed
A20: =A19+1 -> 18 | B20: =DATE(2025,10,29) -> 45959 | C20: Added Netting agreement table for Moodys database | D20: ALL | E20: High | F20: Completed

Sheet Stage_master
A1: No. | B1: Stage_master | C1: Description | D1: TableType | E1: DataNature | F1: DataNature note | I1: Event | J1: Impact to..
A2: 1 | B2: ='All Table_V4_Clean'!A3 -> entity_master | C2: ='All Table_V4_Clean'!A4 -> This table represents the authoritative, enterprise-wide obligor registry. It stores the top-level identity of each customer group, legal entity, or economic group used for credit risk, Basel, TFRS 9, Moody’s mapping, and BOT DER_CPEN.Entity Id. | D2: Master | E2: Static | F2: Maintained by Credit Risk / KYC teams; changes infrequently except for rating updates, group restructuring, or regulatory classification changes. | I2: update MTM from ThaiBMA
A3: =A2+1 -> 2 | B3: ='All Table_V4_Clean'!A21 -> counterparty_master | C3: ='All Table_V4_Clean'!A22 -> This table serves as the single, authoritative repository for all external and internal entities with which the bank conducts treasury business. | D3: Master | E3: Static | F3: Updated manually by KYC / customer on-boarding and credit teams. | I3: update accru int daily
A4: =A3+1 -> 3 | B4: ='All Table_V4_Clean'!A42 -> security_master | C4: This table is a comprehensive catalog of every financial instrument the bank can trade or hold, aligned with standards from the Thai Bond Market Association (ThaiBMA). | D4: Master | E4: Static | F4: Updated manually from ThaiBMA / market data feeds when new issues are added or terms change. | I4: update margin call
A5: =A4+1 -> 4 | B5: ='All Table_V4_Clean'!A70 -> portfolio_master | C5: This table allows for the logical segregation of the bank's treasury positions according to their strategic intent. | D5: Master | E5: Static | F5: Rarely changes; configuration-driven (set up by Treasury/Accounting policy). | I5: update maturity
A6: =A5+1 -> 5 | B6: ='All Table_V4_Clean'!A80 -> netting_agreement | C6: This table contains the master information for all legally enforceable netting and collateral agreements (e.g., ISDA, GMRA) established between the institution and its counterparties. Each record defines the scope, effective period, and key legal attributes governing how financial transactions (e.g., swaps, repos, FX, securities lending) are netted, margined, and settled. | D6: Master | E6: Static | F6: Legal data, created or amended infrequently when agreements are executed, amended, or terminated. | I6: coupon payment
A7: =A6+1 -> 6 | B7: ='All Table_V4_Clean'!A100 -> interbank_deals | C7: This table records all interbank lending (placements) and borrowing (takings) transactions. | D7: Transaction | E7: Event-driven | F7: Daily deal capture from treasury dealing systems (front office). | I7: floating rate reprice
A8: =A7+1 -> 7 | B8: ='All Table_V4_Clean'!A129 -> interbank_interest_schedule | C8: This child table maintains the interest period schedule (floating) and reset details for each interbank lending or borrowing deal recorded in the Interbank_Deals table. Each record represents a single interest accrual period, storing the applicable benchmark rate, margin, effective interest rate, and accrued interest for that specific period. | D8: Transaction (Child) | E8: Derived | F8: System-generated and updated from Interbank_Deals; adjusted on rate reset, accrual runs, and at period close. | I8: Input deal buy sell lend borrow | J8: cost & Realized P/L
A9: =A8+1 -> 8 | B9: ='All Table_V4_Clean'!A142 -> repo_trades | C9: This table captures the master details of each REPO or Reverse REPO transaction. | D9: Transaction | E9: Event-driven | F9: Daily capture of new repo / reverse repo deals, linked to collateral and margining.
A10: =A9+1 -> 9 | B10: ='All Table_V4_Clean'!A173 -> collateral_positions | C10: This is a child table to Repo_Trades, providing a granular log of all securities allocated as collateral for a specific trade. | D10: Transaction (Child) | E10: Event-driven | F10: Updated when repo trades are booked, collateral is allocated/substituted, or positions roll/mature.
A11: =A10+1 -> 10 | B11: ='All Table_V4_Clean'!A189 -> bond_trades | C11: This table records all outright purchases and sales of bonds for the bank's investment portfolios. | D11: Transaction | E11: Event-driven | F11: Populated by trade capture from dealing systems; each record is a buy/sell event.
A12: =A11+1 -> 11 | B12: ='All Table_V4_Clean'!A205 -> bond_transactions | C12: This table captures all bond trading activities at the transaction level executed by the bank across its investment and trading portfolios. Each record represents a single trade event, providing full details of the commercial terms, settlement information, pricing attributes, coupon characteristics, and valuation data associated with that transaction. | D12: Transaction | E12: Event-driven | F12: Detailed trade-level event store; may be sourced from multiple front-office systems and normalized here.
A13: =A12+1 -> 12 | B13: ='All Table_V4_Clean'!A240 -> bond_positions | C13: This table maintains the current holding details for each bond investment. Each row represents a unique position in a bond under a specific portfolio. | D13: Position | E13: Derived | F13: Derived from Bond_Transactions / Bond_Trades via end-of-day position building and lifecycle events (buys, sells, transfers, maturities).
A14: =A13+1 -> 13 | B14: ='All Table_V4_Clean'!A268 -> position_costing | C14: This table maintains the current cost basis and realized P&L state for each active bond position. Each record represents the aggregated weighted-average cost (WAC) of all buy transactions linked to a position, as well as the cumulative realized gain/loss from any partial disposals. The table is updated whenever a buy or sell transaction occurs. It supports valuation, accounting, and audit purposes by preserving a clear linkage between trade events, cost accumulation, and realized results. | D14: Analytical | E14: Derived | F14: Updated by the costing engine whenever trades (buys/sells/transfers) affect the position’s cost basis or realized P&L.
A15: =A14+1 -> 14 | B15: ='All Table_V4_Clean'!A282 -> position_realization_events | C15: This table serves as an immutable journal of realized P&L events for bond positions. Each record represents a single realization event (e.g., a sale or transfer-out) capturing the clean-price differential between the sale and the weighted-average cost at that time. | D15: Journal | E15: Event-driven | F15: Appended when a realization event occurs; never updated or deleted (immutable audit log).
A16: =A15+1 -> 15 | B16: ='All Table_V4_Clean'!A298 -> margin_calls | C16: This table records all daily margin call events arising from collateralized trading relationships such as repo, reverse repo, and OTC derivative agreements (e.g., GMRA, ISDA). Each record represents a calculated margin requirement based on mark-to-market exposure as of a specific valuation date, adjusted for thresholds, minimum transfer amounts (MTA), and rounding rules. The table provides a clear workflow and audit trail from exposure calculation through to margin agreement, settlement, and reconciliation. | D16: Control | E16: Derived | F16: Calculated by the margin engine from exposure and collateral data at each valuation date; workflow-driven (Pending → Agreed → Settled).
A17: =A16+1 -> 16 | B17: ='All Table_V4_Clean'!A313 -> cash_margin_movements | C17: This table records all cash-based collateral (margin) movements exchanged between the institution and its counterparties under collateralized agreements such as GMRA (Repo / Reverse Repo). It represents the cash-side lifecycle of margining, acting as the operational mirror of exposure and margin call calculations. Each row captures a single cash event—posting, receiving, returning, or adjusting margin—and provides a full audit trail from margin call through settlement and reconciliation. The table also maintains a running outstanding margin balance per margin_call_id and supports the accrual of interest receivable on cash margin that we have posted (typical Repo case), in accordance with GMRA terms. | D17: Journal / Transaction | E17: Event-driven | F17: Populated when margin cash is instructed/settled (BAHTNET/SWIFT); used for cash & collateral reconciliation.
A18: =A17+1 -> 17 | B18: ='All Table_V4_Clean'!A336 -> limit_utilization | C18: This table provides an immutable, auditable log of every transaction that impacts a credit limit, enabling true pre-trade and post-trade limit checking. | D18: Control | E18: Event-driven | F18: Updated whenever exposures change (new trades, maturities, margining, adjustments); supports limit monitoring and MIS.
A19: =A18+1 -> 18 | B19: ='All Table_V4_Clean'!A352 -> entity_counterparty | C19: ='All Table_V4_Clean'!A353 -> This table defines which counterparties are linked to which entity (obligor group) and which parent limit they are allowed to use. ใช้เก็บ mapping ว่า Entity ID ประกอบด้วย Counterparty ID อะไรบ้าง และทุกตัวใช้วงเงิน Parent ใดร่วมกัน | D19: Master | E19: Static | F19: Updated when group structures change, when counterparties are added/removed, or when shared limit assignments are revised. Used for mapping Entity → Counterparty → Parent Limit for group-level limit enforcement.
B24: Event type to update data in table | C24: Related Table | D24: Department in Charge
B25: Create new Counterparty input | C25: counterparty_master, entity_master, entity_counterparty | D25: Back Office
B26: Create new Security input(Reverse REPO,Bond Buy) | C26: security_master | D26: Back Office
B27: Credit limit update & newly add | C27: limit_utilization | D27: Back Office
B28: REPO setup GMRA
B29: update MTM from ThaiBMA | D29: Back Office
B30: update accru int daily
B31: update margin call
B32: update maturity
B33: coupon payment
B34: floating rate reprice
B35: Input deal buy sell lend borrow

Sheet Accouting QA
A1: # | B1: Q | C1: Ans as of 24 Nov
A2: 1 | B2: สามารถใช้ตัว Accrued Interest ที่ ThaiBMA report (mark-to-market) มาโดยตรงได้ไหมสำหรับการรายงานบัญชี หรือจะต้องปรับอะไรเพิ่ม? | C2: Pending Acc team to check
A3: 2 | B3: Flow การ reconcile ระหว่าง Treasury → ThaiBMA → Accounting GL ต้องใช้ข้อมูลอะไรบ้าง และ format ไหน | C3: Pending Acc team to check
A4: 3 | B4: Journal entries ที่ทีมบัญชีใช้สำหรับการรับรู้ / ปิดบัญชี / reversal ของดอกเบี้ยค้างรับเป็นอย่างไร
A9: Step | B9: Owner | C9: Output
A10: Accrued calculation (ThaiBMA / Treasury System) feed daily to Datamart | B10: Treasury | C10: Position-level accrued interest
A11: Mapping classification (FVOCI, AC, FVTPL) | B11: Accounting | C11: Classification logic
A12: GL Posting (Journal Entry) | B12: Accounting | C12: P&L + BS impact
A13: Reconciliation | B13: Treasury + Accounting | C13: Break-down and adjustments
A14: Reporting (FS, BOT, Management) | B14: Accounting | C14: Final consolidation

Sheet Sheet39
A4: No. | B4: Event | C4: Product | D4: Source of data | E4: Impact to..
E5: Table | F5: Field
A6: 1 | B6: update MTM from ThaiBMA | C6: Bond | D6: Thai BMA website | E6: bond_trades | F6: clean_price_trade
C7: Bond | D7: Thai BMA website | E7: bond_transactions | F7: clean_price_trade | G7: clean_price | H7: accrued_interest | I7: dirty_price
C8: Bond | D8: Thai BMA website | E8: position_realization_events | F8: sell_clean_price_pct
C9: Bond | D9: Thai BMA website | E9: bond_positions | F9: avg_book_clean_price_pct | G9: clean_price | H9: accrued_interest | I9: dirty_price
C10: Bond | D10: Thai BMA website | E10: Collateral_Positions | F10: market_value
A12: 2 | B12: update accrued interest income daily | C12: Bond | D12: Thai BMA website | E12: bond_transactions | F12: accrued_interest
C13: Bond | D13: Thai BMA website | E13: bond_positions | F13: accrued_interest
C14: Interbank lending/borrowing | D14: Treasury System Database | E14: interbank_deals | F14: accrued_interest
A16: 3 | B16: update margin call daily | C16: Bond | D16: Thai BMA website | E16: Collateral_Positions | F16: market_value
C17: Reverse repo/Repo | D17: Treasury System Database | E17: margin_calls | F17: call_type | G17: call_amount
C18: Reverse repo/Repo | D18: Treasury System Database | E18: Repo_Trades | F18: purchase_price
C19: Reverse repo/Repo | D19: Treasury System Database | E19: Cash_Margin_Movements | F19: amount
A21: 4 | B21: update maturity
A24: 5 | B24: coupon payment | C24: Bond | D24: Thai BMA website | E24: bond_transactions | F24: trade_type = Coupon | G24: accrued_interest
E25: bond_positions | F25: accrued_interest
E26: position_realization_events | F26: accrued_int_realized
B28: floating rate reprice | C28: Bond
C29: Interbank lending/borrowing
B33: Input deal buy sell lend borrow | E33: cost & Realized P/L

Sheet All Table_V4_Clean
A1: Timestamp update as of | B1: 46037.479
A3: entity_master
A4: This table represents the authoritative, enterprise-wide obligor registry. It stores the top-level identity of each customer group, legal entity, or economic group used for credit risk, Basel, TFRS 9, Moody’s mapping, and BOT DER_CPEN.Entity Id.
A6: Column Name | B6: Data Type | C6: Description | D6: Example | E6: Primary key/Foreign key | F6: Allow Null | G6: Remark
A7: entity_id | B7: VARCHAR(40) | C7: Top-level unique identifier for the obligor or customer group. Used as the BOT DER_CPEN.Entity Id and compatible with Moody’s ENTITY_CODE. This identifier is systematically constructed by concatenating "entity_short_name + juristic_registration_number" to ensure uniqueness and consistency across counterparty_master, entity_master, and regulatory reporting. This is the primary key that counterparty_master.entity_id references. | D7: =CONCAT(D9,D13) -> BBL0107536000374 | E7: PK | F7: No
A8: entity_name | B8: VARCHAR(255) | C8: Full legal name of the entity/obligor. Often the same as Counterparty_Master.legal_name, but stored here at obligor/group level. | D8: Bangkok Bank PCL | E8: - | F8: No
A9: entity_short_name | B9: VARCHAR(10) | C9: Short name / abbreviation used in risk reporting. | D9: BBL | E9: - | F9: Yes
A10: entity_type | B10: VARCHAR(50) | C10: Fine-grained Basel/Moody’s obligor classification (BANK, BANK_SOV, PSE, CORP_HVCRE, SME_PF, INDIV, SOV, SUPRA, etc.). Used for regulatory RW, EAD grouping, and Moody’s mapped class. | D10: BANK | E10: - | F10: No
A11: industry_sector | B11: VARCHAR(50) | C11: User-defined industry sector (Moody’s INDUSTRY_SECTOR). Used for concentration analysis. | D11: FINANCIALS | E11: - | F11: Yes
A12: country_code | B12: CHAR(3) | C12: Country of domicile for country risk and Basel mapping. | D12: TH | E12: - | F12: No
A13: juristic_registration_number | B13: VARCHAR(20) | C13: เลขจดทะเบียนนิติบุคคล / เลขนิติบุคคล (13 digits for Thai juristic entities). Used for KYC, BOT reporting, and obligor-level regulatory mapping. | D13: 0107536000374 | E13: - | F13: No
A14: registered_capital_amount | B14: DECIMAL(20,2) | C14: ทุนจดทะเบียนของนิติบุคคล (Registered Capital of the entity). | D14: 40000000000 | E14: - | F14: Yes
A15: financials_currency | B15: CHAR(3) | C15: Currency for financials. | D15: THB | F15: Yes
A16: g_sib_type | B16: CHAR(1) | C16: G-SIB / D-SIB classification (G/D/NULL). | D16: D | E16: - | F16: Yes
A17: created_date | B17: DATE | C17: Record creation timestamp. | D17: 45301 | E17: - | F17: No
A18: last_updated_date | B18: DATE | C18: Record last update timestamp. | D18: 45853 | E18: - | F18: Yes
A21: counterparty_master
A22: This table serves as the single, authoritative repository for all external and internal entities with which the bank conducts treasury business.
A24: Column Name | B24: Data Type | C24: Description | D24: Example | E24: Primary key/Foreign key | F24: Allow Null | G24: Remark
A25: entity_id | B25: VARCHAR(40) | C25: Unique reference number identifying a person, juristic person, group of persons, group of juristic persons, or customer group. May represent either (a) an internal identifier used within the financial institution, or (b) an external reference number used for BOT data submission. | D25: BBL0107536000374 | E25: FK → entity_master.entity_id | F25: No
A26: counterparty_id | B26: VARCHAR(40) | C26: Unique system-generated identifier for the counterparty. | D26: 101 | E26: PK | F26: Yes
A27: legal_name | B27: VARCHAR(255) | C27: The full legal name of the entity. | D27: Bangkok Bank PCL | E27: - | F27: No
A28: short_code | B28: VARCHAR(50) | C28: A short, unique code used for quick identification in user interfaces. | D28: BBL | E28: - | F28: Yes
A29: counterparty_type | B29: VARCHAR(50) | C29: Type of counterparty (e.g., 'Commercial Bank', 'SOE', 'Corporate', 'Central Bank'). | D29: Commercial Bank | E29: - | F29: No
A30: bank_code | B30: VARCHAR(13) | C30: Official identifier assigned by the Bank of Thailand in Sheet 'BANK_CODE'. The format should be Text "XXX". | D30: 001 | E30: - | F30: Yes | G30: Applicable only for financial institutions. Leave blank for corporates.
A31: swift_bic | B31: VARCHAR(11) | C31: The counterparty's Business Identifier Code for SWIFT messaging. | D31: BKKBTHBK | E31: - | F31: Yes | G31: Used for payment, settlement, and messaging systems.
A32: primary_credit_rating | B32: VARCHAR(10) | C32: The primary credit rating from the designated agency. | D32: AA+ | E32: - | F32: Yes
A33: primary_rating_agency | B33: VARCHAR(50) | C33: The name of the primary credit rating agency (e.g., 'Fitch', 'TRIS Rating'). | D33: TRIS Rating | E33: - | F33: Yes
A34: primary_rating_date | B34: DATE | C34: The date the primary rating was assigned or last updated. | D34: 45853 | E34: - | F34: Yes
A35: created_date | B35: DATE | C35: Timestamp of record creation for audit purposes. | D35: 45301 | E35: - | F35: No
A36: last_updated_date | B36: DATE | C36: Timestamp of the last update for audit purposes. | D36: 45853 | E36: - | F36: Yes
A37: involved_party_type | B37: INT | C37: Classification code representing the type of institution or counterparty based on the Bank of Thailand’s (BOT) standardized in sheet “Involved_Party_Type” list. | D37: 176039 | E37: - | F37: No
A38: customer_code | B38: VARCHAR(10) | C38: Bank-defined customer classification code used to identify the type of customer for regulatory, reporting, and business rules (e.g., interest calculation, FCC, interbank classification). Each CIF must be mapped to exactly one customer type. The code is maintained by the bank and aligned with BOT/MFSMCG concepts such as Personal, Juristic Person, Government, Financial Institution (Resident / Non-Resident), etc. Please refer to sheet 'Customer_type_master' for the defition. | D38: 2008 | E38: - | F38: No | G38: Remark: This field is introduced in advance to prepare for future customer classification and regulatory use cases. At this stage, the detailed customer code mapping may not yet be fully defined. From a data model perspective, the preferred approach is to use customer_type_code as the single source of truth, and let downstream processes and reports map this code to required attributes (e.g., residency, interbank, FCC class, sector, etc.) via reference tables. This avoids creating many hard-coded flags (e.g., is_interbank_flag, is_financial_institution_flag, is_government_flag, etc.). In the future, once the customer code mapping is stabilized, this field can become the primary driver and allow removal of overlapping or redundant flags. Otherwise, continuing to add multiple boolean flags will eventually result in a table filled with overlapping indicators that represent the same business meaning in different forms. See sheet 'Customer_type_master'
A39: reside_in_thailand_flag | B39: BOOLEAN | C39: Indicates whether the counterparty is a financial institution that resides in Thailand, in accordance with the Monetary and Financial Statistics Manual and Compilation Guide (MFSMCG) residency classification. - TRUE = Counterparty is resident in Thailand (มีถิ่นฐานอยู่ในประเทศ) - FALSE = Counterparty is non-resident (มีถิ่นฐานอยู่นอกประเทศ) Please refer to sheet 'Resident definition' for the defition. | D39: TRUE | E39: - | F39: No | G39: See sheet 'Resident definition'
A42: security_master
A43: This table is a comprehensive catalog of every financial instrument the bank can trade or hold, aligned with standards from the Thai Bond Market Association (ThaiBMA).
A45: Column Name | B45: Data Type | C45: Description | D45: Example | E45: Primary key/Foreign key | F45: Allow Null | G45: Remark
A46: security_id | B46: VARCHAR(10) | C46: Unique system-generated identifier for the security e.g. The official trading symbol used by ThaiBMA. | D46: LB28DA | E46: PK | F46: No
A47: isin | B47: VARCHAR(12) | C47: International Securities Identification Number. | D47: TH0623038C09 | E47: PK | F47: No
A48: issuer_id | B48: VARCHAR(40) | C48: Identify the issuer. 1 = Govt of Thailand, 2 = BOT, 3 = State Own Enterprise, 4 = Corporate https://www.thaibma.or.th/EN/Issuer/IssuerSearch.aspx | D48: 1 | E48: PK | F48: No
...

Sheet accrued_interest
A1: bond_positions.accrued_interest
A2: Case | B2: Behavior
A3: หลังลงทุน / ไม่มี coupon ยังไม่ถึงงวด | B3: AI เพิ่มขึ้นรายวันตั้งแต่ settlement date
A4: หลัง partial sale | B4: AI คิดใหม่บน nominal ที่เหลือ (ไม่ใช้ของ trade เดิม)
A5: หลัง coupon event | B5: AI reset → เริ่มนับใหม่จาก 0
A6: ขายออกเต็มจำนวน (position closed) | B6: Position.accrued_interest = 0
A7: หลัง maturity | B7: accrued_interest → 0 และไม่มีการ accrue ต่อ
A8: Floating bonds | B8: ใช้อัตรา coupon ล่าสุดจาก bond_transactions (Reset rate)

Sheet Product_table structure
A1: Interbank table structure
A2: The primary purpose of this table is to clearly outline the related tables and key linking fields necessary to record, manage, and track data for each product within the interbank system.
A3: It serves as a quick reference guide summarizing all related tables and key linking fields required for Interbank Lending/Borrowing, Reverse Repo/Repo, and Bond Buying/Selling, illustrating the overall data structure needed to support each product’s operation.
A5: Product | B5: No. | C5: Related table | D5: Key fields
A6: Interbank lending/borrowing | B6: 1 | C6: Counterparty_Master | D6: entity_id | E6: counterparty_id | F6: bank_code
B7: 2 | C7: Limit_Utilization | D7: LimitID | E7: counterparty_id | F7: entity_id
B8: 3 | C8: Interbank_Deals | D8: DealID | E8: counterparty_id | F8: LimitID | G8: entity_id
B9: 4 | C9: Interbank_Interest_Schedule (Child Table) | D9: ScheduleID | E9: DealID
A11: Reverse repo/ Repo | B11: 1 | C11: Netting_Agreement | D11: NettingAgreementID | E11: counterparty_id
B12: 2 | C12: Counterparty_Master | D12: entity_id | E12: counterparty_id | F12: bank_code
B13: 3 | C13: Security_Master | D13: SecurityID
B14: 4 | C14: Limit_Utilization | D14: LimitID | E14: counterparty_id | F14: entity_id
B15: 5 | C15: Repo_Trades | D15: RepoTradeID | E15: counterparty_id | F15: LimitID | G15: entity_id
B16: 6 | C16: Collateral_Positions | D16: CollateralID | E16: RepoTradeID | F16: SecurityID
B17: 7 | C17: Bond_Transactions | D17: TradeID | E17: SecurityID | F17: PortfolioID | G17: counterparty_id | H17: TradeType
B18: 8 | C18: Bond_Positions | D18: PositionID | E18: SecurityID | F18: PortfolioID
B19: 9 | C19: Margin_Calls | D19: MarginCallID | E19: counterparty_id | F19: RepoTradeID
B20: 10 | C20: Cash_Margin_Movements | D20: CashMarginMovementID | E20: MarginCallID | F20: counterparty_id | G20: RepoTradeID
A23: Bond buying/ selling | B23: 1 | C23: Counterparty_Master | D23: entity_id | E23: counterparty_id | F23: bank_code
B24: 2 | C24: Security_Master | D24: SecurityID
B25: 3 | C25: Portfolio_Master | D25: PortfolioID
B26: 4 | C26: Bond_Trades | D26: BondTradeID | E26: PortfolioID | F26: SecurityID
B27: 5 | C27: Bond_Transactions | D27: TradeID | E27: SecurityID | F27: PortfolioID | G27: counterparty_id | H27: TradeType
B28: 6 | C28: Bond_Positions | D28: PositionID | E28: SecurityID | F28: PortfolioID
B29: 7 | C29: Position_Costing | D29: CostingID | E29: PositionID
B30: 8 | C30: Position_RealizationEvents | D30: RealizationID | E30: PositionID | F30: TradeID

Sheet cashmargin
F1: PAY
A2: cash_margin_movements | F2: RECEIVE | H2: sum by margin_call_id | L2: cal AI only negative outstanding_balance
A3: cash_margin_movement_id | B3: margin_call_id | C3: counterparty_id | D3: repo_trade_id | E3: call_currency | F3: movement_type | G3: amount | H3: outstanding_balance | I3: value_date | J3: created_timestamp | K3: bank_account_code | L3: accrued_int_payable | M3: daily_accrued_int_payable
A4: 1 | B4: 1 | C4: 101 | D4: 70001 | E4: THB | F4: RECEIVE | G4: 2100000 | H4: 0 | I4: 45909 | J4: 45909.625 | K4: MRGN_THSCCB01
A5: 2 | B5: 2 | C5: 102 | D5: 7703 | E5: THB | F5: RECEIVE | G5: 5500000 | H5: 5500000 | I5: 45930 | J5: 45930.625 | K5: MRGN_THSCCB02
A6: 3 | B6: 3 | C6: 102 | D6: 70004 | E6: THB | F6: PAY | G6: -600000 | H6: -600000 | I6: 45929 | J6: 45929.844 | K6: MRGN_THSCCB03
A7: 4 | B7: 1 | C7: 101 | D7: 70001 | E7: THB | F7: PAY | G7: -2100000 | H7: 0 | I7: 45915 | J7: 45909.625 | K7: MRGN_THSCCB01 | L7: 0
A11: Outstanding Balance | B11: Daily Accrued Interest | C11: Cumulative Accrued Interest
A12: ≥ 0 | B12: 0 | C12: 0 (reset)
A13: < 0 | B13: Calculated | C13: Accumulates

Sheet Data Month N >>

Sheet V4_Result_30 Sep 2025
A1: Export as of | B1: =DATE(2025,9,30) -> 45930 | D1: Timestamp update as of | E1: 46037.666
A3: counterparty_master
A4: {=TRANSPOSE('All Table_V4_Clean'!A25:A39)} -> entity_id | B4: counterparty_id | C4: legal_name | D4: short_code | E4: counterparty_type | F4: bank_code | G4: swift_bic | H4: primary_credit_rating | I4: primary_rating_agency | J4: primary_rating_date | K4: created_date | L4: last_updated_date | M4: involved_party_type | N4: customer_code | O4: reside_in_thailand_flag
A5: =RRP_1_V4_Sep25!B13 -> BBL0107536000374 | B5: =RRP_1_V4_Sep25!C13 -> 101 | C5: =RRP_1_V4_Sep25!D13 -> BANGKOK BANK PCL | D5: =RRP_1_V4_Sep25!E13 -> BBL | E5: =RRP_1_V4_Sep25!F13 -> Commercial Bank | F5: =RRP_1_V4_Sep25!G13 -> 002 | G5: =RRP_1_V4_Sep25!H13 -> BKKBTHBK | H5: =RRP_1_V4_Sep25!I13 -> AA- | ... M5: =RRP_1_V4_Sep25!N13 -> 176039 | N5: 2008 | O5: TRUE
A6: =RRP_2_V4_Sep25!B13 -> KBANK0107536000315 | B6: =RRP_2_V4_Sep25!C13 -> 102 | C6: =RRP_2_V4_Sep25!D13 -> KASIKORNBANK PCL | D6: =RRP_2_V4_Sep25!E13 -> KBANK | E6: =RRP_2_V4_Sep25!F13 -> Commercial Bank | F6: =RRP_2_V4_Sep25!G13 -> 004 | G6: =RRP_2_V4_Sep25!H13 -> KASITHBK | H6: =RRP_2_V4_Sep25!I13 -> AA | ... M6: =RRP_2_V4_Sep25!N13 -> 176039 | N6: 2008 | O6: TRUE
A7: =Repo_1_V4_Sep25!B13 -> KTB107537000882 | B7: =Repo_1_V4_Sep25!C13 -> 103 | C7: =Repo_1_V4_Sep25!D13 -> KRUNGTHAI BANK PCL | D7: =Repo_1_V4_Sep25!E13 -> KTB | E7: =Repo_1_V4_Sep25!F13 -> Commercial Bank | F7: =Repo_1_V4_Sep25!G13 -> 006 | G7: =Repo_1_V4_Sep25!H13 -> KRTHTHBK | H7: =Repo_1_V4_Sep25!I13 -> AA+ | ... M7: =Repo_1_V4_Sep25!N13 -> 176039 | N7: 2008 | O7: TRUE
A8: ='IB Lend_V4_Sep25'!A12 -> CIMB0107537002338 | B8: ='IB Lend_V4_Sep25'!B12 -> 104 | C8: ='IB Lend_V4_Sep25'!C12 -> CIMB THAI BANK PCL | D8: ='IB Lend_V4_Sep25'!D12 -> CIMB | E8: ='IB Lend_V4_Sep25'!E12 -> Commercial Bank | F8: ='IB Lend_V4_Sep25'!F12 -> 022 | G8: ='IB Lend_V4_Sep25'!G12 -> UBOBTHBK | H8: ='IB Lend_V4_Sep25'!H12 -> AA(THA) | ... M8: ='IB Lend_V4_Sep25'!M12 -> 176039 | N8: 2008 | O8: TRUE
A10: security_master
A11: {=TRANSPOSE('All Table_V4_Clean'!A46:A68)} -> security_id | B11: isin | C11: issuer_id | D11: unique_id | E11: instrument_type | F11: issue_date | G11: maturity_date | H11: coupon_rate | I11: coupon_margin | J11: coupon_reference_rate | K11: coupon_frequency | L11: coupon_day_count_conv | M11: currency | N11: country | O11: bond_structure | P11: rating_tris | Q11: rating_fitch | R11: is_eligible_bot_repo_collateral | S11: is_eligible_crm_collateral | T11: status | U11: status_timestamp | V11: coupon_rate_type | W11: cross_default
A12: ='Bond buy_1_V4_Sep25'!B21 -> GSB26OA | B12: ='Bond buy_1_V4_Sep25'!C21 -> TH1029036A07 | C12: ='Bond buy_1_V4_Sep25'!D21 -> 3 | D12: ='Bond buy_1_V4_Sep25'!E21 -> 176017 | E12: ='Bond buy_1_V4_Sep25'!F21 -> SOE Bond | F12: ='Bond buy_1_V4_Sep25'!G21 -> 43754 | G12: ='Bond buy_1_V4_Sep25'!H21 -> 46311 | H12: ='Bond buy_1_V4_Sep25'!I21 -> 1.69 | ... V12: ='Bond buy_1_V4_Sep25'!W21 -> Fixed | W12: FALSE
A13: ='Bond buy_1_V4_Sep25'!B22 -> LB616A | B13: ='Bond buy_1_V4_Sep25'!C22 -> TH0623B3B607 | C13: ='Bond buy_1_V4_Sep25'!D22 -> 1 | D13: ='Bond buy_1_V4_Sep25'!E22 -> 176015 | E13: ='Bond buy_1_V4_Sep25'!F22 -> Gov Bond | F13: ='Bond buy_1_V4_Sep25'!G22 -> 40606 | G13: ='Bond buy_1_V4_Sep25'!H22 -> 58974 | H13: ='Bond buy_1_V4_Sep25'!I22 -> 4.85 | ... V13: ='Bond buy_1_V4_Sep25'!W22 -> Fixed | W13: FALSE
A14: ='Bond buy_1_V4_Sep25'!B23 -> TB26128A | B14: ='Bond buy_1_V4_Sep25'!C23 -> TH0623A76183 | C14: ='Bond buy_1_V4_Sep25'!D23 -> 1 | D14: ='Bond buy_1_V4_Sep25'!E23 -> 176015 | E14: ='Bond buy_1_V4_Sep25'!F23 -> T-Bill | F14: ='Bond buy_1_V4_Sep25'!G23 -> 45868 | G14: ='Bond buy_1_V4_Sep25'!H23 -> 46050 | H14: ='Bond buy_1_V4_Sep25'!I23 -> 0 | ... V14: ='Bond buy_1_V4_Sep25'!W23 -> Fixed | W14: FALSE
A15: ='Bond buy_1_V4_Sep25'!B24 -> BOT25NA | B15: ='Bond buy_1_V4_Sep25'!C24 -> TH0655035B00 | C15: ='Bond buy_1_V4_Sep25'!D24 -> 2 | D15: ='Bond buy_1_V4_Sep25'!E24 -> 001 | E15: ='Bond buy_1_V4_Sep25'!F24 -> BOT Bond | F15: ='Bond buy_1_V4_Sep25'!G24 -> 45236 | G15: ='Bond buy_1_V4_Sep25'!H24 -> 45967 | H15: ='Bond buy_1_V4_Sep25'!I24 -> 2.58 | ... V15: ='Bond buy_1_V4_Sep25'!W24 -> Fixed | W15: FALSE
A16: ='Bond buy_1_V4_Sep25'!B25 -> TB26211A | B16: ='Bond buy_1_V4_Sep25'!C25 -> TH0623076286 | C16: ='Bond buy_1_V4_Sep25'!D25 -> 1 | D16: ='Bond buy_1_V4_Sep25'!E25 -> 176015 | E16: ='Bond buy_1_V4_Sep25'!F25 -> T-Bill | F16: ='Bond buy_1_V4_Sep25'!G25 -> 45882 | G16: ='Bond buy_1_V4_Sep25'!H25 -> 46064 | H16: ='Bond buy_1_V4_Sep25'!I25 -> 0 | ... V16: ='Bond buy_1_V4_Sep25'!W25 -> Fixed | W16: FALSE
A17: ='Bond buy_1_V4_Sep25'!B26 -> BOTF267A | B17: ='Bond buy_1_V4_Sep25'!C26 -> TH0655036711 | C17: ='Bond buy_1_V4_Sep25'!D26 -> 2 | D17: ='Bond buy_1_V4_Sep25'!E26 -> 001 | E17: ='Bond buy_1_V4_Sep25'!F26 -> BOT Bond | F17: ='Bond buy_1_V4_Sep25'!G26 -> 45474 | G17: ='Bond buy_1_V4_Sep25'!H26 -> 46204 | H17: ='Bond buy_1_V4_Sep25'!I26 -> 1.68404 | ... V17: ='Bond buy_1_V4_Sep25'!W26 -> Floating | W17: FALSE
A18: =RRP_1_V4_Sep25!B19 -> LB29DA | B18: =RRP_1_V4_Sep25!C19 -> TH0623039C07 | C18: =RRP_1_V4_Sep25!D19 -> 1 | D18: =RRP_1_V4_Sep25!E19 -> 176015 | E18: =RRP_1_V4_Sep25!F19 -> Gov Bond | F18: =RRP_1_V4_Sep25!G19 -> 43784 | G18: =RRP_1_V4_Sep25!H19 -> 47469 | H18: =RRP_1_V4_Sep25!I19 -> 1.6 | ... V18: =RRP_1_V4_Sep25!W19 -> Fixed | W18: FALSE
A19: =RRP_2_V4_Sep25!B19 -> LB28DA | B19: =RRP_2_V4_Sep25!C19 -> TH0623038C09 | C19: =RRP_2_V4_Sep25!D19 -> 1 | D19: =RRP_2_V4_Sep25!E19 -> 176015 | E19: =RRP_2_V4_Sep25!F19 -> Gov Bond | F19: =RRP_2_V4_Sep25!G19 -> 43294 | G19: =RRP_2_V4_Sep25!H19 -> 47104 | H19: =RRP_2_V4_Sep25!I19 -> 2.875 | ... V19: =RRP_2_V4_Sep25!W19 -> Fixed | W19: FALSE
A20: ='Bond Buy-Sell_V4_Sep25 + Oct25'!A24 -> EXIM266A | B20: ='Bond Buy-Sell_V4_Sep25 + Oct25'!B24 -> TH0624036602 | C20: ='Bond Buy-Sell_V4_Sep25 + Oct25'!C24 -> 3 | D20: ='Bond Buy-Sell_V4_Sep25 + Oct25'!D24 -> 035 | E20: ='Bond Buy-Sell_V4_Sep25 + Oct25'!E24 -> SOE Bond | F20: ='Bond Buy-Sell_V4_Sep25 + Oct25'!F24 -> 45083 | G20: ='Bond Buy-Sell_V4_Sep25 + Oct25'!G24 -> 46179 | H20: ='Bond Buy-Sell_V4_Sep25 + Oct25'!H24 -> 2.71 | ... V20: ='Bond Buy-Sell_V4_Sep25 + Oct25'!V24 -> Fixed | W20: FALSE
A22: portfolio_master
A23: {=TRANSPOSE('All Table_V4_Clean'!A74:A78)} -> portfolio_id | B23: portfolio_name | C23: portfolio_manager | D23: accounting_treatment | E23: created_timestamp
A24: ='Bond buy_1_V4_Sep25'!B34 -> 301 | B24: ='Bond buy_1_V4_Sep25'!C34 -> AMC - Govt | C24: ='Bond buy_1_V4_Sep25'!D34 -> Treasury Desk | D24: ='Bond buy_1_V4_Sep25'!E34 -> AMC | E24: ='Bond buy_1_V4_Sep25'!F34 -> 45839
A25: ='Bond buy_1_V4_Sep25'!B35 -> 302 | B25: ='Bond buy_1_V4_Sep25'!C35 -> AMC - T-Bill | C25: ='Bond buy_1_V4_Sep25'!D35 -> Treasury Desk | D25: ='Bond buy_1_V4_Sep25'!E35 -> AMC | E25: ='Bond buy_1_V4_Sep25'!F35 -> 45839
A26: ='Bond buy_1_V4_Sep25'!B36 -> 303 | B26: ='Bond buy_1_V4_Sep25'!C36 -> AMC - BOT bond | C26: ='Bond buy_1_V4_Sep25'!D36 -> Treasury Desk | D26: ='Bond buy_1_V4_Sep25'!E36 -> AMC | E26: ='Bond buy_1_V4_Sep25'!F36 -> 45839
A27: ='Bond buy_1_V4_Sep25'!B37 -> 401 | B27: ='Bond buy_1_V4_Sep25'!C37 -> FVOCI - T-Bill | C27: ='Bond buy_1_V4_Sep25'!D37 -> Treasury Desk | D27: ='Bond buy_1_V4_Sep25'!E37 -> FVOCI | E27: ='Bond buy_1_V4_Sep25'!F37 -> 45839
A28: ='Bond buy_1_V4_Sep25'!B38 -> 402 | B28: ='Bond buy_1_V4_Sep25'!C38 -> FVOCI - BOT bond | C28: ='Bond buy_1_V4_Sep25'!D38 -> Treasury Desk | D28: ='Bond buy_1_V4_Sep25'!E38 -> FVOCI | E28: ='Bond buy_1_V4_Sep25'!F38 -> 45839
A29: ='Bond buy_1_V4_Sep25'!B39 -> 403 | B29: ='Bond buy_1_V4_Sep25'!C39 -> FVOCI - SOE | C29: ='Bond buy_1_V4_Sep25'!D39 -> Treasury Desk | D29: ='Bond buy_1_V4_Sep25'!E39 -> FVOCI | E29: ='Bond buy_1_V4_Sep25'!F39 -> 45839
A32: netting_agreement
A33: {=TRANSPOSE('All Table_V4_Clean'!A84:A98)} -> netting_agreement_id | B33: counterparty_id | C33: netting_set_id | D33: agreement_type | E33: netting_type | F33: collateral_contract_type | G33: trade_date | H33: value_date | I33: maturity_date | J33: is_replacement | K33: replaced_agreement_id | L33: settlement_currency | M33: created_at | N33: updated_at | O33: agreement_status
A34: =RRP_1_V4_Sep25!B31 -> GMRA_2023_BB | B34: =RRP_1_V4_Sep25!C31 -> 101 | C34: =RRP_1_V4_Sep25!D31 -> 20001 | D34: =RRP_1_V4_Sep25!E31 -> GMRA | E34: =RRP_1_V4_Sep25!F31 -> COLLATERAL | F34: =RRP_1_V4_Sep25!G31 -> REP | G34: =RRP_1_V4_Sep25!H31 -> 45823 | H34: =RRP_1_V4_Sep25!I31 -> 45839 | ... O34: =RRP_1_V4_Sep25!P31 -> Active
A35: =RRP_2_V4_Sep25!B31 -> GMRA_2023_KB | B35: =RRP_2_V4_Sep25!C31 -> 102 | C35: =RRP_2_V4_Sep25!D31 -> 20002 | D35: =RRP_2_V4_Sep25!E31 -> GMRA | E35: =RRP_2_V4_Sep25!F31 -> COLLATERAL | F35: =RRP_2_V4_Sep25!G31 -> REP | G35: =RRP_2_V4_Sep25!H31 -> 45823 | H35: =RRP_2_V4_Sep25!I31 -> 45839 | ... O35: =RRP_2_V4_Sep25!P31 -> Active
A36: =Repo_1_V4_Sep25!B25 -> GMRA_2023_KT | B36: =Repo_1_V4_Sep25!C25 -> 103 | C36: =Repo_1_V4_Sep25!D25 -> 20003 | D36: =Repo_1_V4_Sep25!E25 -> GMRA | E36: =Repo_1_V4_Sep25!F25 -> COLLATERAL | F36: =Repo_1_V4_Sep25!G25 -> REP | G36: =Repo_1_V4_Sep25!H25 -> 45823 | H36: =Repo_1_V4_Sep25!I25 -> 45839 | ... O36: =Repo_1_V4_Sep25!P25 -> Active
A37: =Repo_2_V4_Sep25!B25 -> GMRA_2024_KB | B37: =Repo_2_V4_Sep25!C25 -> 102 | C37: =Repo_2_V4_Sep25!D25 -> 20004 | D37: =Repo_2_V4_Sep25!E25 -> GMRA | E37: =Repo_2_V4_Sep25!F25 -> COLLATERAL | F37: =Repo_2_V4_Sep25!G25 -> REP | G37: =Repo_2_V4_Sep25!H25 -> 45823 | H37: =Repo_2_V4_Sep25!I25 -> 45839 | ... O37: =Repo_2_V4_Sep25!P25 -> Active
A40: limit_utilization
A41: {=TRANSPOSE('All Table_V4_Clean'!A340:A350)} -> limit_id | B41: counterparty_id | C41: limit_type | D41: currency | E41: available_line | F41: total_credit_line | G41: utilization_amount | H41: credit_line_approve_date | I41: timestamp | J41: created_date | K41: entity_id
A42: =RRP_1_V4_Sep25!B25 -> 1001 | B42: =RRP_1_V4_Sep25!C25 -> 101 | C42: =RRP_1_V4_Sep25!D25 -> REPO_LIMIT | D42: =RRP_1_V4_Sep25!E25 -> THB | E42: =RRP_1_V4_Sep25!F25 -> 800000000 | F42: =RRP_1_V4_Sep25!G25 -> 1000000000 | G42: =RRP_1_V4_Sep25!H25 -> 200000000 | H42: =RRP_1_V4_Sep25!I25 -> 45782 | ... K42: =RRP_1_V4_Sep25!L25 -> BBL0107536000374
A43: =RRP_2_V4_Sep25!B25 -> 1002 | B43: =RRP_2_V4_Sep25!C25 -> 102 | C43: =RRP_2_V4_Sep25!D25 -> REPO_LIMIT | D43: =RRP_2_V4_Sep25!E25 -> THB | E43: =RRP_2_V4_Sep25!F25 -> 900000000 | F43: =RRP_2_V4_Sep25!G25 -> 1000000000 | G43: =RRP_2_V4_Sep25!H25 -> 300000000 | H43: =RRP_2_V4_Sep25!I25 -> 45782 | ... K43: =RRP_2_V4_Sep25!L25 -> KBANK0107536000315
A44: ='IB Lend_V4_Sep25'!A135 -> 2001 | B44: ='IB Lend_V4_Sep25'!B135 -> 101 | C44: ='IB Lend_V4_Sep25'!C135 -> PLACEMENT_LIMIT | D44: ='IB Lend_V4_Sep25'!D135 -> THB | E44: ='IB Lend_V4_Sep25'!E135 -> 500000000 | F44: ='IB Lend_V4_Sep25'!F135 -> 1000000000 | G44: ='IB Lend_V4_Sep25'!G135 -> 500000000 | H44: ='IB Lend_V4_Sep25'!H135 -> 45901 | ... K44: ='IB Lend_V4_Sep25'!K135 -> BBL0107536000374
A45: ='IB Lend_V4_Sep25'!A136 -> 2002 | B45: ='IB Lend_V4_Sep25'!B136 -> 104 | C45: ='IB Lend_V4_Sep25'!C136 -> PLACEMENT_LIMIT | D45: ='IB Lend_V4_Sep25'!D136 -> THB | E45: ='IB Lend_V4_Sep25'!E136 -> 400000000 | F45: ='IB Lend_V4_Sep25'!F136 -> 500000000 | G45: ='IB Lend_V4_Sep25'!G136 -> 100000000 | H45: ='IB Lend_V4_Sep25'!H136 -> 45828 | ... K45: ='IB Lend_V4_Sep25'!K136 -> CIMB0107537002338
A48: repo_trades
A49: {=TRANSPOSE('All Table_V4_Clean'!A146:A171)} -> repo_trade_id | B49: trade_date | C49: trade_type | D49: counterparty_id | E49: netting_agreement_id | F49: netting_set_id | G49: nominal_amount | H49: purchase_date | I49: repurchase_date | J49: purchase_price | K49: repurchase_price | L49: currency | M49: reference_rate_id | N49: interest_rate_type | O49: interest_rate | P49: reference_rate | Q49: margin | R49: day_count_convention | S49: repo_rate | T49: term | U49: repo_out_flag | V49: repo_in_flag | W49: status | X49: limit_id | Y49: accrued_interest | Z49: entity_id
...

Sheet V4_Result_31 Oct 2025
A1: Export as of | B1: =DATE(2025,10,31) -> 45961 | D1: Timestamp update as of | E1: 46037.666
A3: ='V4_Result_30 Sep 2025'!A3 -> counterparty_master
A4: {=TRANSPOSE('All Table_V4_Clean'!A25:A39)} -> entity_id | B4: counterparty_id | C4: legal_name | D4: short_code | E4: counterparty_type | F4: bank_code | G4: swift_bic | H4: primary_credit_rating | I4: primary_rating_agency | J4: primary_rating_date | K4: created_date | L4: last_updated_date | M4: involved_party_type | N4: customer_code | O4: reside_in_thailand_flag
A5: =RRP_1_V4_Sep25!B13 -> BBL0107536000374 | B5: =RRP_1_V4_Sep25!C13 -> 101 | C5: =RRP_1_V4_Sep25!D13 -> BANGKOK BANK PCL | D5: =RRP_1_V4_Sep25!E13 -> BBL | E5: =RRP_1_V4_Sep25!F13 -> Commercial Bank | F5: =RRP_1_V4_Sep25!G13 -> 002 | G5: =RRP_1_V4_Sep25!H13 -> BKKBTHBK | H5: =RRP_1_V4_Sep25!I13 -> AA- | ... M5: =RRP_1_V4_Sep25!N13 -> 176039 | N5: 2008 | O5: TRUE
A6: =RRP_2_V4_Sep25!B13 -> KBANK0107536000315 | B6: =RRP_2_V4_Sep25!C13 -> 102 | C6: =RRP_2_V4_Sep25!D13 -> KASIKORNBANK PCL | D6: =RRP_2_V4_Sep25!E13 -> KBANK | E6: =RRP_2_V4_Sep25!F13 -> Commercial Bank | F6: =RRP_2_V4_Sep25!G13 -> 004 | G6: =RRP_2_V4_Sep25!H13 -> KASITHBK | H6: =RRP_2_V4_Sep25!I13 -> AA | ... M6: =RRP_2_V4_Sep25!N13 -> 176039 | N6: 2008 | O6: TRUE
A7: =Repo_1_V4_Sep25!B13 -> KTB107537000882 | B7: =Repo_1_V4_Sep25!C13 -> 103 | C7: =Repo_1_V4_Sep25!D13 -> KRUNGTHAI BANK PCL | D7: =Repo_1_V4_Sep25!E13 -> KTB | E7: =Repo_1_V4_Sep25!F13 -> Commercial Bank | F7: =Repo_1_V4_Sep25!G13 -> 006 | G7: =Repo_1_V4_Sep25!H13 -> KRTHTHBK | H7: =Repo_1_V4_Sep25!I13 -> AA+ | ... M7: =Repo_1_V4_Sep25!N13 -> 176039 | N7: 2008 | O7: TRUE
A8: ='IB Lend_V4_Oct25'!A12 -> CIMB0107537002338 | B8: ='IB Lend_V4_Oct25'!B12 -> 104 | C8: ='IB Lend_V4_Oct25'!C12 -> CIMB THAI BANK PCL | D8: ='IB Lend_V4_Oct25'!D12 -> CIMB | E8: ='IB Lend_V4_Oct25'!E12 -> Commercial Bank | F8: ='IB Lend_V4_Oct25'!F12 -> 022 | G8: ='IB Lend_V4_Oct25'!G12 -> UBOBTHBK | H8: ='IB Lend_V4_Oct25'!H12 -> AA(THA) | ... M8: ='IB Lend_V4_Oct25'!M12 -> 176039 | N8: 2008 | O8: TRUE
A9: ='IB Lend_V4_Oct25'!A11 -> SCB0107536000102 | B9: ='IB Lend_V4_Oct25'!B11 -> 113 | C9: ='IB Lend_V4_Oct25'!C11 -> SIAM COMMERCIAL BANK PCL | D9: ='IB Lend_V4_Oct25'!D11 -> SCB | E9: ='IB Lend_V4_Oct25'!E11 -> Commercial Bank | F9: ='IB Lend_V4_Oct25'!F11 -> 084 | G9: ='IB Lend_V4_Oct25'!G11 -> SICOTHBK | H9: ='IB Lend_V4_Oct25'!H11 -> AA+(THA) | ... M9: ='IB Lend_V4_Oct25'!M11 -> 176039 | N9: 2008 | O9: TRUE
A11: ='V4_Result_30 Sep 2025'!A10 -> security_master
A12: {=TRANSPOSE('All Table_V4_Clean'!A46:A68)} -> security_id | B12: isin | C12: issuer_id | D12: unique_id | E12: instrument_type | F12: issue_date | G12: maturity_date | H12: coupon_rate | I12: coupon_margin | J12: coupon_reference_rate | K12: coupon_frequency | L12: coupon_day_count_conv | M12: currency | N12: country | O12: bond_structure | P12: rating_tris | Q12: rating_fitch | R12: is_eligible_bot_repo_collateral | S12: is_eligible_crm_collateral | T12: status | U12: status_timestamp | V12: coupon_rate_type | W12: cross_default
A13: ='Bond buy_1_V4_Sep25'!B21 -> GSB26OA | B13: ='Bond buy_1_V4_Sep25'!C21 -> TH1029036A07 | C13: ='Bond buy_1_V4_Sep25'!D21 -> 3 | D13: ='Bond buy_1_V4_Sep25'!E21 -> 176017 | E13: ='Bond buy_1_V4_Sep25'!F21 -> SOE Bond | F13: ='Bond buy_1_V4_Sep25'!G21 -> 43754 | G13: ='Bond buy_1_V4_Sep25'!H21 -> 46311 | H13: ='Bond buy_1_V4_Sep25'!I21 -> 1.69 | ... V13: ='Bond buy_1_V4_Sep25'!W21 -> Fixed | W13: FALSE
A14: ='Bond buy_1_V4_Sep25'!B22 -> LB616A | B14: ='Bond buy_1_V4_Sep25'!C22 -> TH0623B3B607 | C14: ='Bond buy_1_V4_Sep25'!D22 -> 1 | D14: ='Bond buy_1_V4_Sep25'!E22 -> 176015 | E14: ='Bond buy_1_V4_Sep25'!F22 -> Gov Bond | F14: ='Bond buy_1_V4_Sep25'!G22 -> 40606 | G14: ='Bond buy_1_V4_Sep25'!H22 -> 58974 | H14: ='Bond buy_1_V4_Sep25'!I22 -> 4.85 | ... V14: ='Bond buy_1_V4_Sep25'!W22 -> Fixed | W14: FALSE
A15: ='Bond buy_1_V4_Sep25'!B23 -> TB26128A | B15: ='Bond buy_1_V4_Sep25'!C23 -> TH0623A76183 | C15: ='Bond buy_1_V4_Sep25'!D23 -> 1 | D15: ='Bond buy_1_V4_Sep25'!E23 -> 176015 | E15: ='Bond buy_1_V4_Sep25'!F23 -> T-Bill | F15: ='Bond buy_1_V4_Sep25'!G23 -> 45868 | G15: ='Bond buy_1_V4_Sep25'!H23 -> 46050 | H15: ='Bond buy_1_V4_Sep25'!I23 -> 0 | ... V15: ='Bond buy_1_V4_Sep25'!W23 -> Fixed | W15: FALSE
A16: ='Bond buy_1_V4_Sep25'!B24 -> BOT25NA | B16: ='Bond buy_1_V4_Sep25'!C24 -> TH0655035B00 | C16: ='Bond buy_1_V4_Sep25'!D24 -> 2 | D16: ='Bond buy_1_V4_Sep25'!E24 -> 001 | E16: ='Bond buy_1_V4_Sep25'!F24 -> BOT Bond | F16: ='Bond buy_1_V4_Sep25'!G24 -> 45236 | G16: ='Bond buy_1_V4_Sep25'!H24 -> 45967 | H16: ='Bond buy_1_V4_Sep25'!I24 -> 2.58 | ... V16: ='Bond buy_1_V4_Sep25'!W24 -> Fixed | W16: FALSE
A17: ='Bond buy_1_V4_Sep25'!B25 -> TB26211A | B17: ='Bond buy_1_V4_Sep25'!C25 -> TH0623076286 | C17: ='Bond buy_1_V4_Sep25'!D25 -> 1 | D17: ='Bond buy_1_V4_Sep25'!E25 -> 176015 | E17: ='Bond buy_1_V4_Sep25'!F25 -> T-Bill | F17: ='Bond buy_1_V4_Sep25'!G25 -> 45882 | G17: ='Bond buy_1_V4_Sep25'!H25 -> 46064 | H17: ='Bond buy_1_V4_Sep25'!I25 -> 0 | ... V17: ='Bond buy_1_V4_Sep25'!W25 -> Fixed | W17: FALSE
A18: ='Bond buy_1_V4_Sep25'!B26 -> BOTF267A | B18: ='Bond buy_1_V4_Sep25'!C26 -> TH0655036711 | C18: ='Bond buy_1_V4_Sep25'!D26 -> 2 | D18: ='Bond buy_1_V4_Sep25'!E26 -> 001 | E18: ='Bond buy_1_V4_Sep25'!F26 -> BOT Bond | F18: ='Bond buy_1_V4_Sep25'!G26 -> 45474 | G18: ='Bond buy_1_V4_Sep25'!H26 -> 46204 | H18: ='Bond buy_1_V4_Sep25'!I26 -> 1.68404 | ... V18: ='Bond buy_1_V4_Sep25'!W26 -> Floating | W18: FALSE
A19: =RRP_1_V4_Sep25!B19 -> LB29DA | B19: =RRP_1_V4_Sep25!C19 -> TH0623039C07 | C19: =RRP_1_V4_Sep25!D19 -> 1 | D19: =RRP_1_V4_Sep25!E19 -> 176015 | E19: =RRP_1_V4_Sep25!F19 -> Gov Bond | F19: =RRP_1_V4_Sep25!G19 -> 43784 | G19: =RRP_1_V4_Sep25!H19 -> 47469 | H19: =RRP_1_V4_Sep25!I19 -> 1.6 | ... V19: =RRP_1_V4_Sep25!W19 -> Fixed | W19: FALSE
A20: =RRP_2_V4_Sep25!B19 -> LB28DA | B20: =RRP_2_V4_Sep25!C19 -> TH0623038C09 | C20: =RRP_2_V4_Sep25!D19 -> 1 | D20: =RRP_2_V4_Sep25!E19 -> 176015 | E20: =RRP_2_V4_Sep25!F19 -> Gov Bond | F20: =RRP_2_V4_Sep25!G19 -> 43294 | G20: =RRP_2_V4_Sep25!H19 -> 47104 | H20: =RRP_2_V4_Sep25!I19 -> 2.875 | ... V20: =RRP_2_V4_Sep25!W19 -> Fixed | W20: FALSE
A21: ='Bond Buy-Sell_V4_Sep25 + Oct25'!A24 -> EXIM266A | B21: ='Bond Buy-Sell_V4_Sep25 + Oct25'!B24 -> TH0624036602 | C21: ='Bond Buy-Sell_V4_Sep25 + Oct25'!C24 -> 3 | D21: ='Bond Buy-Sell_V4_Sep25 + Oct25'!D24 -> 035 | E21: ='Bond Buy-Sell_V4_Sep25 + Oct25'!E24 -> SOE Bond | F21: ='Bond Buy-Sell_V4_Sep25 + Oct25'!F24 -> 45083 | G21: ='Bond Buy-Sell_V4_Sep25 + Oct25'!G24 -> 46179 | H21: ='Bond Buy-Sell_V4_Sep25 + Oct25'!H24 -> 2.71 | ... V21: ='Bond Buy-Sell_V4_Sep25 + Oct25'!V24 -> Fixed | W21: FALSE
A23: ='V4_Result_30 Sep 2025'!A22 -> portfolio_master
A24: {=TRANSPOSE('All Table_V4_Clean'!A74:A78)} -> portfolio_id | B24: portfolio_name | C24: portfolio_manager | D24: accounting_treatment | E24: created_timestamp
A25: ='Bond buy_1_V4_Sep25'!B34 -> 301 | B25: ='Bond buy_1_V4_Sep25'!C34 -> AMC - Govt | C25: ='Bond buy_1_V4_Sep25'!D34 -> Treasury Desk | D25: ='Bond buy_1_V4_Sep25'!E34 -> AMC | E25: ='Bond buy_1_V4_Sep25'!F34 -> 45839
A26: ='Bond buy_1_V4_Sep25'!B35 -> 302 | B26: ='Bond buy_1_V4_Sep25'!C35 -> AMC - T-Bill | C26: ='Bond buy_1_V4_Sep25'!D35 -> Treasury Desk | D26: ='Bond buy_1_V4_Sep25'!E35 -> AMC | E26: ='Bond buy_1_V4_Sep25'!F35 -> 45839
A27: ='Bond buy_1_V4_Sep25'!B36 -> 303 | B27: ='Bond buy_1_V4_Sep25'!C36 -> AMC - BOT bond | C27: ='Bond buy_1_V4_Sep25'!D36 -> Treasury Desk | D27: ='Bond buy_1_V4_Sep25'!E36 -> AMC | E27: ='Bond buy_1_V4_Sep25'!F36 -> 45839
A28: ='Bond buy_1_V4_Sep25'!B37 -> 401 | B28: ='Bond buy_1_V4_Sep25'!C37 -> FVOCI - T-Bill | C28: ='Bond buy_1_V4_Sep25'!D37 -> Treasury Desk | D28: ='Bond buy_1_V4_Sep25'!E37 -> FVOCI | E28: ='Bond buy_1_V4_Sep25'!F37 -> 45839
A29: ='Bond buy_1_V4_Sep25'!B38 -> 402 | B29: ='Bond buy_1_V4_Sep25'!C38 -> FVOCI - BOT bond | C29: ='Bond buy_1_V4_Sep25'!D38 -> Treasury Desk | D29: ='Bond buy_1_V4_Sep25'!E38 -> FVOCI | E29: ='Bond buy_1_V4_Sep25'!F38 -> 45839
A30: ='Bond buy_1_V4_Sep25'!B39 -> 403 | B30: ='Bond buy_1_V4_Sep25'!C39 -> FVOCI - SOE | C30: ='Bond buy_1_V4_Sep25'!D39 -> Treasury Desk | D30: ='Bond buy_1_V4_Sep25'!E39 -> FVOCI | E30: ='Bond buy_1_V4_Sep25'!F39 -> 45839
A33: ='V4_Result_30 Sep 2025'!A32 -> netting_agreement
A34: {=TRANSPOSE('All Table_V4_Clean'!A84:A98)} -> netting_agreement_id | B34: counterparty_id | C34: netting_set_id | D34: agreement_type | E34: netting_type | F34: collateral_contract_type | G34: trade_date | H34: value_date | I34: maturity_date | J34: is_replacement | K34: replaced_agreement_id | L34: settlement_currency | M34: created_at | N34: updated_at | O34: agreement_status
A35: =RRP_1_V4_Sep25!B31 -> GMRA_2023_BB | B35: =RRP_1_V4_Sep25!C31 -> 101 | C35: =RRP_1_V4_Sep25!D31 -> 20001 | D35: =RRP_1_V4_Sep25!E31 -> GMRA | E35: =RRP_1_V4_Sep25!F31 -> COLLATERAL | F35: =RRP_1_V4_Sep25!G31 -> REP | G35: =RRP_1_V4_Sep25!H31 -> 45823 | H35: =RRP_1_V4_Sep25!I31 -> 45839 | ... O35: =RRP_1_V4_Sep25!P31 -> Active
A36: =RRP_2_V4_Sep25!B31 -> GMRA_2023_KB | B36: =RRP_2_V4_Sep25!C31 -> 102 | C36: =RRP_2_V4_Sep25!D31 -> 20002 | D36: =RRP_2_V4_Sep25!E31 -> GMRA | E36: =RRP_2_V4_Sep25!F31 -> COLLATERAL | F36: =RRP_2_V4_Sep25!G31 -> REP | G36: =RRP_2_V4_Sep25!H31 -> 45823 | H36: =RRP_2_V4_Sep25!I31 -> 45839 | ... O36: =RRP_2_V4_Sep25!P31 -> Active
A37: =Repo_1_V4_Sep25!B25 -> GMRA_2023_KT | B37: =Repo_1_V4_Sep25!C25 -> 103 | C37: =Repo_1_V4_Sep25!D25 -> 20003 | D37: =Repo_1_V4_Sep25!E25 -> GMRA | E37: =Repo_1_V4_Sep25!F25 -> COLLATERAL | F37: =Repo_1_V4_Sep25!G25 -> REP | G37: =Repo_1_V4_Sep25!H25 -> 45823 | H37: =Repo_1_V4_Sep25!I25 -> 45839 | ... O37: =Repo_1_V4_Sep25!P25 -> Active
A38: =Repo_2_V4_Sep25!B25 -> GMRA_2024_KB | B38: =Repo_2_V4_Sep25!C25 -> 102 | C38: =Repo_2_V4_Sep25!D25 -> 20004 | D38: =Repo_2_V4_Sep25!E25 -> GMRA | E38: =Repo_2_V4_Sep25!F25 -> COLLATERAL | F38: =Repo_2_V4_Sep25!G25 -> REP | G38: =Repo_2_V4_Sep25!H25 -> 45823 | H38: =Repo_2_V4_Sep25!I25 -> 45839 | ... O38: =Repo_2_V4_Sep25!P25 -> Active
A41: ='V4_Result_30 Sep 2025'!A40 -> limit_utilization
A42: {=TRANSPOSE('All Table_V4_Clean'!A340:A350)} -> limit_id | B42: counterparty_id | C42: limit_type | D42: currency | E42: available_line | F42: total_credit_line | G42: utilization_amount | H42: credit_line_approve_date | I42: timestamp | J42: created_date | K42: entity_id
A43: =RRP_1_V4_Sep25!B25 -> 1001 | B43: =RRP_1_V4_Sep25!C25 -> 101 | C43: =RRP_1_V4_Sep25!D25 -> REPO_LIMIT | D43: =RRP_1_V4_Sep25!E25 -> THB | E43: =RRP_1_V4_Sep25!F25 -> 800000000 | F43: =RRP_1_V4_Sep25!G25 -> 1000000000 | G43: =RRP_1_V4_Sep25!H25 -> 200000000 | H43: =RRP_1_V4_Sep25!I25 -> 45782 | ... K43: =RRP_1_V4_Sep25!L25 -> BBL0107536000374
A44: =RRP_2_V4_Sep25!B25 -> 1002 | B44: =RRP_2_V4_Sep25!C25 -> 102 | C44: =RRP_2_V4_Sep25!D25 -> REPO_LIMIT | D44: =RRP_2_V4_Sep25!E25 -> THB | E44: =RRP_2_V4_Sep25!F25 -> 900000000 | F44: =RRP_2_V4_Sep25!G25 -> 1000000000 | G44: =RRP_2_V4_Sep25!H25 -> 300000000 | H44: =RRP_2_V4_Sep25!I25 -> 45782 | ... K44: =RRP_2_V4_Sep25!L25 -> KBANK0107536000315
A45: ='IB Lend_V4_Sep25'!A135 -> 2001 | B45: ='IB Lend_V4_Sep25'!B135 -> 101 | C45: ='IB Lend_V4_Sep25'!C135 -> PLACEMENT_LIMIT | D45: ='IB Lend_V4_Sep25'!D135 -> THB | E45: ='IB Lend_V4_Sep25'!E135 -> 500000000 | F45: ='IB Lend_V4_Sep25'!F135 -> 1000000000 | G45: ='IB Lend_V4_Sep25'!G135 -> 500000000 | H45: ='IB Lend_V4_Sep25'!H135 -> 45901 | ... K45: ='IB Lend_V4_Sep25'!K135 -> BBL0107536000374
A46: ='IB Lend_V4_Oct25'!A114 -> 2002 | B46: ='IB Lend_V4_Oct25'!B114 -> 104 | C46: ='IB Lend_V4_Oct25'!C114 -> PLACEMENT_LIMIT | D46: ='IB Lend_V4_Oct25'!D114 -> THB | E46: ='IB Lend_V4_Oct25'!E114 -> 400000000 | F46: ='IB Lend_V4_Oct25'!F114 -> 500000000 | G46: ='IB Lend_V4_Oct25'!G114 -> 100000000 | H46: ='IB Lend_V4_Oct25'!H114 -> 45828 | ... K46: ='IB Lend_V4_Oct25'!K114 -> CIMB0107537002338
A47: ='IB Lend_V4_Oct25'!A113 -> 2003 | B47: ='IB Lend_V4_Oct25'!B113 -> 113 | C47: ='IB Lend_V4_Oct25'!C113 -> PLACEMENT_LIMIT | D47: ='IB Lend_V4_Oct25'!D113 -> THB | E47: ='IB Lend_V4_Oct25'!E113 -> 1000000000 | F47: ='IB Lend_V4_Oct25'!F113 -> 500000000 | G47: ='IB Lend_V4_Oct25'!G113 -> 0 | H47: ='IB Lend_V4_Oct25'!H113 -> 45931 | ... K47: ='IB Lend_V4_Oct25'!K113 -> SCB0107536000102
...

